<mujoco model="empty_floor">
  <compiler angle="radian" />

  <option timestep="0.001" gravity="0 0 -9.81" integrator="implicitfast" impratio="10">
      <flag contact="enable" energy="enable" gravity="enable" />
  </option>

  <visual>
    <rgba haze="0.15 0.25 0.35 1" />
    <global azimuth="120" elevation="-20" />
  </visual>





  <asset>
    <mesh name="table" file="D:\WorkFiles\robopal\robopal\assets\scenes\../objects/table/table.STL" scale="1.0 1.0 0.66" />

    <texture type="skybox" builtin="gradient" rgb1="0.68 0.68 0.68" rgb2="0.3 0.3 0.3" width="512" height="3072" />
    <texture name="groundplane" type="2d" builtin="checker" mark="edge" rgb1="0.68 0.68 0.68" rgb2="0.8 0.8 0.8" markrgb="0.68 0.68 0.68" width="300" height="300" />
    <material name="groundplane" reflectance="0.2" shininess="0.0" specular="0.0" texrepeat="5 5" texture="groundplane" texuniform="true" />

    <texture name="wood" type="2d" file="D:\WorkFiles\robopal\robopal\assets\textures\wood.png" />
    <material name="wood" texture="wood" texrepeat="1 1" texuniform="true" rgba="0.68 0.68 0.68 1" />
  <material class="panda" name="white" rgba="1 1 1 1" />
    <material class="panda" name="off_white" rgba="0.901961 0.921569 0.929412 1" />
    <material class="panda" name="dark_grey" rgba="0.25 0.25 0.25 1" />
    <material class="panda" name="green" rgba="0 1 0 1" />
    <material class="panda" name="light_blue" rgba="0.039216 0.541176 0.780392 1" />

    
    <mesh name="0_link0_c" file="D:\WorkFiles\robopal\robopal\assets\models\manipulators\Panda\meshes/link0.stl" />
    <mesh name="0_link1_c" file="D:\WorkFiles\robopal\robopal\assets\models\manipulators\Panda\meshes/link1.stl" />
    <mesh name="0_link2_c" file="D:\WorkFiles\robopal\robopal\assets\models\manipulators\Panda\meshes/link2.stl" />
    <mesh name="0_link3_c" file="D:\WorkFiles\robopal\robopal\assets\models\manipulators\Panda\meshes/link3.stl" />
    <mesh name="0_link4_c" file="D:\WorkFiles\robopal\robopal\assets\models\manipulators\Panda\meshes/link4.stl" />
    <mesh name="0_link5_c0" file="D:\WorkFiles\robopal\robopal\assets\models\manipulators\Panda\meshes/link5_collision_0.obj" />
    <mesh name="0_link5_c1" file="D:\WorkFiles\robopal\robopal\assets\models\manipulators\Panda\meshes/link5_collision_1.obj" />
    <mesh name="0_link5_c2" file="D:\WorkFiles\robopal\robopal\assets\models\manipulators\Panda\meshes/link5_collision_2.obj" />
    <mesh name="0_link6_c" file="D:\WorkFiles\robopal\robopal\assets\models\manipulators\Panda\meshes/link6.stl" />
    <mesh name="0_link7_c" file="D:\WorkFiles\robopal\robopal\assets\models\manipulators\Panda\meshes/link7.stl" />

    
    <mesh file="D:\WorkFiles\robopal\robopal\assets\models\manipulators\Panda\meshes/link0_0.obj" />
    <mesh file="D:\WorkFiles\robopal\robopal\assets\models\manipulators\Panda\meshes/link0_1.obj" />
    <mesh file="D:\WorkFiles\robopal\robopal\assets\models\manipulators\Panda\meshes/link0_2.obj" />
    <mesh file="D:\WorkFiles\robopal\robopal\assets\models\manipulators\Panda\meshes/link0_3.obj" />
    <mesh file="D:\WorkFiles\robopal\robopal\assets\models\manipulators\Panda\meshes/link0_4.obj" />
    <mesh file="D:\WorkFiles\robopal\robopal\assets\models\manipulators\Panda\meshes/link0_5.obj" />
    <mesh file="D:\WorkFiles\robopal\robopal\assets\models\manipulators\Panda\meshes/link0_7.obj" />
    <mesh file="D:\WorkFiles\robopal\robopal\assets\models\manipulators\Panda\meshes/link0_8.obj" />
    <mesh file="D:\WorkFiles\robopal\robopal\assets\models\manipulators\Panda\meshes/link0_9.obj" />
    <mesh file="D:\WorkFiles\robopal\robopal\assets\models\manipulators\Panda\meshes/link0_10.obj" />
    <mesh file="D:\WorkFiles\robopal\robopal\assets\models\manipulators\Panda\meshes/link0_11.obj" />
    <mesh file="D:\WorkFiles\robopal\robopal\assets\models\manipulators\Panda\meshes/link1.obj" />
    <mesh file="D:\WorkFiles\robopal\robopal\assets\models\manipulators\Panda\meshes/link2.obj" />
    <mesh file="D:\WorkFiles\robopal\robopal\assets\models\manipulators\Panda\meshes/link3_0.obj" />
    <mesh file="D:\WorkFiles\robopal\robopal\assets\models\manipulators\Panda\meshes/link3_1.obj" />
    <mesh file="D:\WorkFiles\robopal\robopal\assets\models\manipulators\Panda\meshes/link3_2.obj" />
    <mesh file="D:\WorkFiles\robopal\robopal\assets\models\manipulators\Panda\meshes/link3_3.obj" />
    <mesh file="D:\WorkFiles\robopal\robopal\assets\models\manipulators\Panda\meshes/link4_0.obj" />
    <mesh file="D:\WorkFiles\robopal\robopal\assets\models\manipulators\Panda\meshes/link4_1.obj" />
    <mesh file="D:\WorkFiles\robopal\robopal\assets\models\manipulators\Panda\meshes/link4_2.obj" />
    <mesh file="D:\WorkFiles\robopal\robopal\assets\models\manipulators\Panda\meshes/link4_3.obj" />
    <mesh file="D:\WorkFiles\robopal\robopal\assets\models\manipulators\Panda\meshes/link5_0.obj" />
    <mesh file="D:\WorkFiles\robopal\robopal\assets\models\manipulators\Panda\meshes/link5_1.obj" />
    <mesh file="D:\WorkFiles\robopal\robopal\assets\models\manipulators\Panda\meshes/link5_2.obj" />
    <mesh file="D:\WorkFiles\robopal\robopal\assets\models\manipulators\Panda\meshes/link6_0.obj" />
    <mesh file="D:\WorkFiles\robopal\robopal\assets\models\manipulators\Panda\meshes/link6_1.obj" />
    <mesh file="D:\WorkFiles\robopal\robopal\assets\models\manipulators\Panda\meshes/link6_2.obj" />
    <mesh file="D:\WorkFiles\robopal\robopal\assets\models\manipulators\Panda\meshes/link6_3.obj" />
    <mesh file="D:\WorkFiles\robopal\robopal\assets\models\manipulators\Panda\meshes/link6_4.obj" />
    <mesh file="D:\WorkFiles\robopal\robopal\assets\models\manipulators\Panda\meshes/link6_5.obj" />
    <mesh file="D:\WorkFiles\robopal\robopal\assets\models\manipulators\Panda\meshes/link6_6.obj" />
    <mesh file="D:\WorkFiles\robopal\robopal\assets\models\manipulators\Panda\meshes/link6_7.obj" />
    <mesh file="D:\WorkFiles\robopal\robopal\assets\models\manipulators\Panda\meshes/link6_8.obj" />
    <mesh file="D:\WorkFiles\robopal\robopal\assets\models\manipulators\Panda\meshes/link6_9.obj" />
    <mesh file="D:\WorkFiles\robopal\robopal\assets\models\manipulators\Panda\meshes/link6_10.obj" />
    <mesh file="D:\WorkFiles\robopal\robopal\assets\models\manipulators\Panda\meshes/link6_11.obj" />
    <mesh file="D:\WorkFiles\robopal\robopal\assets\models\manipulators\Panda\meshes/link6_12.obj" />
    <mesh file="D:\WorkFiles\robopal\robopal\assets\models\manipulators\Panda\meshes/link6_13.obj" />
    <mesh file="D:\WorkFiles\robopal\robopal\assets\models\manipulators\Panda\meshes/link6_14.obj" />
    <mesh file="D:\WorkFiles\robopal\robopal\assets\models\manipulators\Panda\meshes/link6_15.obj" />
    <mesh file="D:\WorkFiles\robopal\robopal\assets\models\manipulators\Panda\meshes/link6_16.obj" />
    <mesh file="D:\WorkFiles\robopal\robopal\assets\models\manipulators\Panda\meshes/link7_0.obj" />
    <mesh file="D:\WorkFiles\robopal\robopal\assets\models\manipulators\Panda\meshes/link7_1.obj" />
    <mesh file="D:\WorkFiles\robopal\robopal\assets\models\manipulators\Panda\meshes/link7_2.obj" />
    <mesh file="D:\WorkFiles\robopal\robopal\assets\models\manipulators\Panda\meshes/link7_3.obj" />
    <mesh file="D:\WorkFiles\robopal\robopal\assets\models\manipulators\Panda\meshes/link7_4.obj" />
    <mesh file="D:\WorkFiles\robopal\robopal\assets\models\manipulators\Panda\meshes/link7_5.obj" />
    <mesh file="D:\WorkFiles\robopal\robopal\assets\models\manipulators\Panda\meshes/link7_6.obj" />
    <mesh file="D:\WorkFiles\robopal\robopal\assets\models\manipulators\Panda\meshes/link7_7.obj" />
  <mesh name="0_electric_gripper_base" file="D:\WorkFiles\robopal\robopal\assets\models\grippers\rethink_gripper\meshes/electric_gripper_base.stl" />
        <mesh name="0_standard_narrow" file="D:\WorkFiles\robopal\robopal\assets\models\grippers\rethink_gripper\meshes/standard_narrow.stl" />
        <mesh name="0_half_round_tip" file="D:\WorkFiles\robopal\robopal\assets\models\grippers\rethink_gripper\meshes/half_round_tip.stl" />
        <mesh name="0_connector_plate" file="D:\WorkFiles\robopal\robopal\assets\models\grippers\rethink_gripper\meshes/connector_plate.stl" />
    </asset>

  <worldbody>
    
    <geom condim="3" material="groundplane" name="floor" pos="0 0 0" size="3 3 .125" type="plane" />
    <light diffuse=".8 .8 .8" dir="0 -.15 -1" directional="false" pos="1 1 8.0" specular="0.3 0.3 0.3" castshadow="false" />
    <light diffuse=".8 .8 .8" dir="0 -.15 -1" directional="false" pos="-3. -3. 8.0" specular="0.3 0.3 0.3" castshadow="false" />
    
    <camera mode="fixed" name="frontview" pos="1.6 0 1.45" quat="0.56 0.43 0.43 0.56" />
    
    <camera mode="fixed" name="birdview" pos="-0.2 0 3.0" quat="0.7071 0 0 0.7071" />
    
    <camera mode="fixed" name="agentview" pos="0.5 0 1.35" quat="0.653 0.271 0.271 0.653" />
    
    <camera mode="fixed" name="sideview" pos="-0.05651774593317116 1.2761224129427358 1.4879572214102434" quat="0.009905065491771751 0.006877963156909582 0.5912228352893879 0.806418094001364" />

    <body name="table" pos="1.0 0.3 0.0" euler="0 0 0">
        <include file="objects/table/table.xml" />
    </body>

  <body name="0_mount_base_link" pos="0 0 0.42">
            <geom type="sphere" size="0.01" contype="0" conaffinity="0" group="1" pos="0 0 0" rgba="1 1 1 1" />
        <light name="top" pos="0 0 2" mode="trackcom" />
    <body name="0_link0" childclass="panda">
      <inertial mass="0.629769" pos="-0.041018 -0.00014 0.049974" fullinertia="0.00315 0.00388 0.004285 8.2904e-7 0.00015 8.2299e-6" />
      <geom mesh="link0_0" material="off_white" class="panda/visual" />
      <geom mesh="link0_1" material="dark_grey" class="panda/visual" />
      <geom mesh="link0_2" material="off_white" class="panda/visual" />
      <geom mesh="link0_3" material="dark_grey" class="panda/visual" />
      <geom mesh="link0_4" material="off_white" class="panda/visual" />
      <geom mesh="link0_5" material="dark_grey" class="panda/visual" />
      <geom mesh="link0_7" material="white" class="panda/visual" />
      <geom mesh="link0_8" material="white" class="panda/visual" />
      <geom mesh="link0_9" material="dark_grey" class="panda/visual" />
      <geom mesh="link0_10" material="off_white" class="panda/visual" />
      <geom mesh="link0_11" material="white" class="panda/visual" />
      <geom mesh="0_link0_c" class="panda/collision" />
      <body name="0_link1" pos="0 0 0.333">
        <inertial mass="4.970684" pos="0.003875 0.002081 -0.04762" fullinertia="0.70337 0.70661 0.0091170 -0.00013900 0.0067720 0.019169" />
        <joint name="0_joint1" pos="0 0 0" axis="0 0 1" limited="true" range="-2.8973 2.8973" damping="0.1" />
        <geom material="white" mesh="link1" class="panda/visual" />
        <geom mesh="0_link1_c" class="panda/collision" />
        <body name="0_link2" quat="1 -1 0 0">
          <inertial mass="0.646926" pos="-0.003141 -0.02872 0.003495" fullinertia="0.0079620 2.8110e-2 2.5995e-2 -3.925e-3 1.0254e-2 7.04e-4" />
          <joint name="0_joint2" pos="0 0 0" axis="0 0 1" limited="true" range="-1.7628 1.7628" damping="0.1" />
          <geom material="white" mesh="link2" class="panda/visual" />
          <geom mesh="0_link2_c" class="panda/collision" />
          <body name="0_link3" pos="0 -0.316 0" quat="1 1 0 0">
            <joint name="0_joint3" pos="0 0 0" axis="0 0 1" limited="true" range="-2.8973 2.8973" damping="0.1" />
            <inertial mass="3.228604" pos="2.7518e-2 3.9252e-2 -6.6502e-2" fullinertia="3.7242e-2 3.6155e-2 1.083e-2 -4.761e-3 -1.1396e-2 -1.2805e-2" />
            <geom mesh="link3_0" material="white" class="panda/visual" />
            <geom mesh="link3_1" material="white" class="panda/visual" />
            <geom mesh="link3_2" material="white" class="panda/visual" />
            <geom mesh="link3_3" material="dark_grey" class="panda/visual" />
            <geom mesh="0_link3_c" class="panda/collision" />
            <body name="0_link4" pos="0.0825 0 0" quat="1 1 0 0">
              <inertial mass="3.587895" pos="-5.317e-2 1.04419e-1 2.7454e-2" fullinertia="2.5853e-2 1.9552e-2 2.8323e-2 7.796e-3 -1.332e-3 8.641e-3" />
              <joint name="0_joint4" pos="0 0 0" axis="0 0 1" limited="true" range="-3.0718 -0.0698" damping="0.1" />
              <geom mesh="link4_0" material="white" class="panda/visual" />
              <geom mesh="link4_1" material="white" class="panda/visual" />
              <geom mesh="link4_2" material="dark_grey" class="panda/visual" />
              <geom mesh="link4_3" material="white" class="panda/visual" />
              <geom mesh="0_link4_c" class="panda/collision" />
              <body name="0_link5" pos="-0.0825 0.384 0" quat="1 -1 0 0">
                <inertial mass="1.225946" pos="-1.1953e-2 4.1065e-2 -3.8437e-2" fullinertia="3.5549e-2 2.9474e-2 8.627e-3 -2.117e-3 -4.037e-3 2.29e-4" />
                <joint name="0_joint5" pos="0 0 0" axis="0 0 1" limited="true" range="-2.8973 2.8973" damping="0.1" />
                <geom mesh="link5_0" material="dark_grey" class="panda/visual" />
                <geom mesh="link5_1" material="white" class="panda/visual" />
                <geom mesh="link5_2" material="white" class="panda/visual" />
                <geom mesh="0_link5_c0" class="panda/collision" />
                <geom mesh="0_link5_c1" class="panda/collision" />
                <geom mesh="0_link5_c2" class="panda/collision" />
                <body name="0_link6" quat="1 1 0 0">
                  <inertial mass="1.666555" pos="6.0149e-2 -1.4117e-2 -1.0517e-2" fullinertia="1.964e-3 4.354e-3 5.433e-3 1.09e-4 -1.158e-3 3.41e-4" />
                  <joint name="0_joint6" pos="0 0 0" axis="0 0 1" limited="true" range="-0.0175 3.7525" damping="0.01" />
                  <geom mesh="link6_0" material="off_white" class="panda/visual" />
                  <geom mesh="link6_1" material="white" class="panda/visual" />
                  <geom mesh="link6_2" material="dark_grey" class="panda/visual" />
                  <geom mesh="link6_3" material="white" class="panda/visual" />
                  <geom mesh="link6_4" material="white" class="panda/visual" />
                  <geom mesh="link6_5" material="white" class="panda/visual" />
                  <geom mesh="link6_6" material="white" class="panda/visual" />
                  <geom mesh="link6_7" material="light_blue" class="panda/visual" />
                  <geom mesh="link6_8" material="light_blue" class="panda/visual" />
                  <geom mesh="link6_9" material="dark_grey" class="panda/visual" />
                  <geom mesh="link6_10" material="dark_grey" class="panda/visual" />
                  <geom mesh="link6_11" material="white" class="panda/visual" />
                  <geom mesh="link6_12" material="green" class="panda/visual" />
                  <geom mesh="link6_13" material="white" class="panda/visual" />
                  <geom mesh="link6_14" material="dark_grey" class="panda/visual" />
                  <geom mesh="link6_15" material="dark_grey" class="panda/visual" />
                  <geom mesh="link6_16" material="white" class="panda/visual" />
                  <geom mesh="0_link6_c" class="panda/collision" />
                  <body name="0_link7" pos="0.088 0 0" quat="1 1 0 0">
                    <inertial mass="7.35522e-01" pos="1.0517e-2 -4.252e-3 6.1597e-2" fullinertia="1.2516e-2 1.0027e-2 4.815e-3 -4.28e-4 -1.196e-3 -7.41e-4" />
                    <joint name="0_joint7" pos="0 0 0" axis="0 0 1" limited="true" range="-2.8973 2.8973" damping="0.01" />
                    <geom mesh="link7_0" material="white" class="panda/visual" />
                    <geom mesh="link7_1" material="dark_grey" class="panda/visual" />
                    <geom mesh="link7_2" material="dark_grey" class="panda/visual" />
                    <geom mesh="link7_3" material="dark_grey" class="panda/visual" />
                    <geom mesh="link7_4" material="dark_grey" class="panda/visual" />
                    <geom mesh="link7_5" material="dark_grey" class="panda/visual" />
                    <geom mesh="link7_6" material="dark_grey" class="panda/visual" />
                    <geom mesh="link7_7" material="white" class="panda/visual" />
                    <geom mesh="0_link7_c" class="panda/collision" />
                    <body name="0_attachment" pos="0 0 0.107" quat="0.3826834 0 0 0.9238795">
                      <site name="0_attachment_site" />
                    <body name="0_gripper_base">
            <site name="0_ft_frame" pos="0 0 0" size="0.01 0.01 0.01" rgba="1 0 0 1" type="sphere" group="1" />
            <inertial pos="0 0 0" quat="-0.5 0.5 0.5 0.5" mass="0.0001" diaginertia="3e-08 2e-08 2e-08" />
            <geom type="mesh" contype="0" conaffinity="0" group="1" mesh="0_connector_plate" name="0_connector_plate" pos="0 0 0.0018" rgba="0.499 0.499 0.499 1" />
            <geom type="mesh" contype="0" conaffinity="0" group="1" mesh="0_electric_gripper_base" name="0_electric_gripper_base" pos="0 0 0.0194" rgba="0.499 0.499 0.499 1" />
            <geom size="0.029 0.05" quat="0 0 0.707107 0.707107" type="cylinder" group="0" name="0_gripper_base_col" pos="0.004 0.0 0.04" />
            
            <body name="0_eef" pos="0 0 0.109" quat="0.707105 0 0 -0.707105">
                <site name="0_grip_site" pos="0 0 0" size="0.005" rgba="1 0 0 0.5" type="sphere" group="1" />
                <site name="0_ee_x" pos="0.1 0 0" size="0.005 .1" quat="0.707105  0 0.707108 0 " rgba="1 0 0 0" type="cylinder" group="1" />
                <site name="0_ee_y" pos="0 0.1 0" size="0.005 .1" quat="0.707105 0.707108 0 0" rgba="0 1 0 0" type="cylinder" group="1" />
                <site name="0_ee_z" pos="0 0 0.1" size="0.005 .1" quat="1 0 0 0" rgba="0 0 1 0" type="cylinder" group="1" />
                
                
            </body>
            <body name="0_l_finger" pos="0 0.01 0.0444">
                <inertial pos="0 0 0" quat="0 0 0 -1" mass="0.0001" diaginertia="0.001 0.001 0.001" />
                <joint name="0_l_finger_joint" pos="0 0 0" axis="0 1 0" type="slide" limited="true" range="-0.0115 0.020833" damping="100" armature="1.0" frictionloss="1.0" />
                <geom name="0_l_finger" quat="0 0 0 -1" type="mesh" contype="0" conaffinity="0" group="1" mesh="0_standard_narrow" rgba="0.499 0.499 0.499 1" />
                <geom size="0.005 0.00675 0.0375" pos="0 0.01725 0.04" quat="0 0 0 -1" type="box" group="0" conaffinity="1" contype="0" name="0_l_finger_g0" friction="0 0 0" />
                <geom size="0.005 0.025 0.0085" pos="-0.005 -0.003 0.0083" quat="0 0 0 -1" type="box" group="0" conaffinity="1" contype="0" name="0_l_finger_g1" friction="0 0 0" />
                <body name="0_l_finger_tip" pos="0 0.01725 0.075">
                    <inertial pos="0 0 0" quat="0 0 0 1" mass="0.0001" diaginertia="0.001 0.001 0.001" />
                    <geom name="0_l_fingertip_g0_vis" quat="0 0 0 1" type="mesh" contype="0" conaffinity="0" group="1" mesh="0_half_round_tip" rgba="0.499 0.499 0.499 1" />
                    <geom size="0.004 0.004 0.0185" pos="0 -0.0045 -0.015" quat="0 0 0 -1" type="box" group="0" conaffinity="1" contype="0" condim="4" name="0_l_fingertip_g0" friction="1 0.05 0.01" />
                    <geom size="0.0035 0.004 0.0165" pos="0 -0.0047 -0.017" type="box" conaffinity="1" contype="0" name="0_l_fingerpad_g0" condim="4" friction="1 0.05 0.01" />
                </body>
            </body>
            <body name="0_r_finger" pos="0 -0.01 0.0444">
                <inertial pos="0 0 0" mass="0.0001" diaginertia="0.001 0.001 0.001" />
                <joint name="0_r_finger_joint" pos="0 0 0" axis="0 -1 0" type="slide" limited="true" range="-0.020833 0.0115" damping="100" armature="1.0" frictionloss="1.0" />
                <geom name="0_r_finger" type="mesh" contype="0" conaffinity="0" group="1" mesh="0_standard_narrow" rgba="0.499 0.499 0.499 1" />
                <geom size="0.005 0.00675 0.0375" pos="0 -0.01725 0.04" type="box" group="0" conaffinity="1" contype="0" name="0_r_finger_g0" friction="0 0 0" />
                <geom size="0.005 0.025 0.0085" pos="0.005 0.003 0.0083" type="box" group="0" conaffinity="1" contype="0" name="0_r_finger_g1" friction="0 0 0" />
                <body name="0_r_finger_tip" pos="0 -0.01725 0.075">
                    <inertial pos="0 0 0" mass="0.0001" diaginertia="0.001 0.001 0.001" />
                    <geom name="0_r_fingertip_g0_vis" type="mesh" contype="0" conaffinity="0" group="1" mesh="0_half_round_tip" rgba="0.499 0.499 0.499 1" />
                    <geom size="0.004 0.004 0.0185" pos="0 0.0045 -0.015" type="box" group="0" conaffinity="1" contype="0" condim="4" name="0_r_fingertip_g0" friction="1 0.05 0.01" />
                    <geom size="0.0035 0.004 0.0165" pos="0 0.0047 -0.017" type="box" conaffinity="1" contype="0" condim="4" name="0_r_fingerpad_g0" friction="1 0.05 0.01" />
                </body>
            </body>
        </body>
    </body>
                  </body>
                </body>
              </body>
            </body>
          </body>
        </body>
      </body>
    </body>
  </body>
    <body name="green_block" pos="0.5 0.0 0.46">
            <joint name="green_block:joint" type="free" damping="0.1" />
            <geom name="green_block" size="0.02 0.02 0.02" rgba="0 1 0 1" type="box" conaffinity="0" contype="0" group="1" />
            <geom name="green_block_collision" size="0.02 0.02 0.02" type="box" conaffinity="1" condim="3" contype="1" group="4" mass="0.02" />
            <site name="green_block" pos="0 0 0" size="0.02 0.02 0.02" rgba="0 1 0 0.5" type="sphere" />
        </body>
    <site name="goal_site" pos="0.4 0.0 0.5" size="0.02 0.02 0.02" rgba="1 0 0 1" type="sphere" /></worldbody>
<actuator><motor ctrllimited="true" ctrlrange="-80.0 80.0" joint="0_joint1" name="0_actuator1" />
        <motor ctrllimited="true" ctrlrange="-80.0 80.0" joint="0_joint2" name="0_actuator2" />
        <motor ctrllimited="true" ctrlrange="-80.0 80.0" joint="0_joint3" name="0_actuator3" />
        <motor ctrllimited="true" ctrlrange="-80.0 80.0" joint="0_joint4" name="0_actuator4" />
        <motor ctrllimited="true" ctrlrange="-80.0 80.0" joint="0_joint5" name="0_actuator5" />
        <motor ctrllimited="true" ctrlrange="-12.0 12.0" joint="0_joint6" name="0_actuator6" />
        <motor ctrllimited="true" ctrlrange="-12.0 12.0" joint="0_joint7" name="0_actuator7" />
    <position ctrllimited="true" ctrlrange="-0.020833 0.0115" joint="0_r_finger_joint" kp="1000" name="0_gripper_r_finger_joint" forcelimited="true" forcerange="-20 20" />
        <position ctrllimited="true" ctrlrange="-0.020833 0.0115" joint="0_l_finger_joint" kp="1000" name="0_gripper_l_finger_joint" forcelimited="true" forcerange="-20 20" />
    </actuator><default><default class="panda">
      <material specular="0.5" shininess="0.25" />
      <joint armature="0.1" damping="1" axis="0 0 1" range="-2.8973 2.8973" />
      <general dyntype="none" biastype="affine" ctrlrange="-2.8973 2.8973" forcerange="-87 87" />
      <default class="finger">
        <joint axis="0 1 0" type="slide" range="0 0.04" />
      </default>

      <default class="panda/visual">
        <geom type="mesh" contype="0" conaffinity="0" group="2" />
      </default>
      <default class="panda/collision">
        <geom type="mesh" group="3" />
      </default>
      <site size="0.001" rgba="0.5 0.5 0.5 0.3" group="4" />
    </default>
  </default><contact /><sensor><force name="0_force_ee" site="0_ft_frame" />
        <torque name="0_torque_ee" site="0_ft_frame" />
    </sensor><equality><joint joint1="0_r_finger_joint" joint2="0_l_finger_joint" />
    </equality></mujoco>